Workbook

Sheet قائمة المستثمرين
A1: ملخص حساب المستثمرين لعام 2024
A3: م | B3: اسم المستثمر | C3: عدد السيارات | D3: الايراد | E3: المصروف | F3: الصافى | G3: المسحوب | H3: المتبقى | I3: رصيد سنوات سابقة | J3: الرصيد
A4: 1 | B4: مقبل ناجي عوض العلوني | C4: 6 | D4: ='مقبل ناجي عوض العلوني'!$AH$9 -> 135998.84 | E4: ='مقبل ناجي عوض العلوني'!$AH$17 -> 28723.259 | F4: ='مقبل ناجي عوض العلوني'!$AH$20 -> 75092.909 | G4: ='مقبل ناجي عوض العلوني'!$AH$21 -> 0 | H4: ='مقبل ناجي عوض العلوني'!$AH$22 -> 75092.909 | I4: ='مقبل ناجي عوض العلوني'!$AH$23 -> 12791 | J4: =H4+I4 -> 87883.909
A5: 2 | B5: رائد الحسيني | C5: 1 | D5: ='رائد الحسيني'!$D$9 -> 35343 | E5: ='رائد الحسيني'!$D$17 -> 0 | F5: ='رائد الحسيني'!$D$20 -> 35343 | G5: ='رائد الحسيني'!$D$21 -> 35343 | H5: ='رائد الحسيني'!$D$22 -> 0 | I5: ='رائد الحسيني'!$D$23 -> 0 | J5: =H5+I5 -> 0
A6: 3 | B6: فايز رابح الشاماني | C6: 4 | D6: ='فايز رابح الشاماني'!$X$9 -> 70381.13 | E6: ='فايز رابح الشاماني'!$X$17 -> 12005.222 | F6: ='فايز رابح الشاماني'!$X$20 -> 40863.136 | G6: ='فايز رابح الشاماني'!$X$21 -> 0 | H6: ='فايز رابح الشاماني'!$X$22 -> 40863.136 | I6: ='فايز رابح الشاماني'!$X$23 -> 0 | J6: =H6+I6 -> 40863.136
A7: 4 | B7: مرام الصاعدي | C7: 1 | D7: ='مرام الصاعدي'!$D$9 -> 19305.757 | E7: ='مرام الصاعدي'!$D$17 -> 2434.0802 | F7: ='مرام الصاعدي'!$D$20 -> 11810.173 | G7: ='مرام الصاعدي'!$D$21 -> 0 | H7: ='مرام الصاعدي'!$D$22 -> 11810.173 | I7: ='مرام الصاعدي'!$D$23 -> 10590 | J7: =H7+I7 -> 22400.173
A8: 5 | B8: بدرية الصاعدي | C8: 1 | D8: ='بدرية الصاعدي'!$D$9 -> 25326.522 | E8: ='بدرية الصاعدي'!$D$17 -> 3570.19 | F8: ='بدرية الصاعدي'!$D$20 -> 15229.432 | G8: ='بدرية الصاعدي'!$D$21 -> 0 | H8: ='بدرية الصاعدي'!$D$22 -> 15229.432 | I8: ='بدرية الصاعدي'!$D$23 -> 30811 | J8: =H8+I8 -> 46040.432
A9: 6 | B9: روان مسعد | C9: 1 | D9: ='روان مسعد'!$D$9 -> 16670.235 | E9: ='روان مسعد'!$D$17 -> 2209.65 | F9: ='روان مسعد'!$D$20 -> 10122.409 | G9: ='روان مسعد'!$D$21 -> 0 | H9: ='روان مسعد'!$D$22 -> 10122.409 | I9: ='روان مسعد'!$D$23 -> 24302.125 | J9: =H9+I9 -> 34424.534
A10: 7 | B10: اميره +نسرين الصاعدي | C10: 1 | D10: ='اميره +نسرين الصاعدي'!$D$9 -> 28898.07 | E10: ='اميره +نسرين الصاعدي'!$D$17 -> 3232.322 | F10: ='اميره +نسرين الصاعدي'!$D$20 -> 17966.023 | G10: ='اميره +نسرين الصاعدي'!$D$21 -> 0 | H10: ='اميره +نسرين الصاعدي'!$D$22 -> 17966.023 | I10: ='اميره +نسرين الصاعدي'!$D$23 -> 27322.382 | J10: =H10+I10 -> 45288.405
A11: 8 | B11: نوال حمدان | C11: 2 | D11: ='نوال حمدان'!$N$9 -> 38984.061 | E11: ='نوال حمدان'!$N$17 -> 7454.9095 | F11: ='نوال حمدان'!$N$20 -> 22070.406 | G11: ='نوال حمدان'!$N$21 -> 0 | H11: ='نوال حمدان'!$N$22 -> 22070.406 | I11: ='نوال حمدان'!$N$23 -> 39567 | J11: =H11+I11 -> 61637.406
A12: 9 | B12: وليد نافع العوفي | C12: 12 | D12: =' وليد نافع العوفي'!$BL$9 -> 230308.11 | E12: =' وليد نافع العوفي'!$BL$17 -> 30895.22 | F12: =' وليد نافع العوفي'!$BL$20 -> 138855.84 | G12: =' وليد نافع العوفي'!$BL$21 -> 0 | H12: =' وليد نافع العوفي'!$BL$22 -> 138855.84 | I12: =' وليد نافع العوفي'!$BL$23 -> 40707 | J12: =H12+I12 -> 179562.84
A13: 10 | B13: فهد الاحمدي | C13: 1 | D13: ='فهد الاحمدي'!$D$9 -> 20284.348 | E13: ='فهد الاحمدي'!$D$17 -> 1711.0646 | F13: ='فهد الاحمدي'!$D$20 -> 13001.298 | G13: ='فهد الاحمدي'!$D$21 -> 0 | H13: ='فهد الاحمدي'!$D$22 -> 13001.298 | I13: ='فهد الاحمدي'!$D$23 -> 31431 | J13: =H13+I13 -> 44432.298
A14: 11 | B14: نوف عبيدالله مبارك العوفي | C14: 7 | D14: ='نوف عبيدالله مبارك العوفي '!$AM$9 -> 149006.73 | E14: ='نوف عبيدالله مبارك العوفي '!$AM$17 -> 13547.041 | F14: ='نوف عبيدالله مبارك العوفي '!$AM$20 -> 94179.659 | G14: ='نوف عبيدالله مبارك العوفي '!$AM$21 -> 0 | H14: ='نوف عبيدالله مبارك العوفي '!$AM$22 -> 94179.659 | I14: ='نوف عبيدالله مبارك العوفي '!$AM$23 -> 67209 | J14: =H14+I14 -> 161388.66
A15: 12 | B15: ايلان العوفي | C15: 1 | D15: ='ايلان العوفي '!$D$9 -> 27776.096 | E15: ='ايلان العوفي '!$D$17 -> 2491.2655 | F15: ='ايلان العوفي '!$D$20 -> 17699.381 | G15: ='ايلان العوفي '!$D$21 -> 0 | H15: ='ايلان العوفي '!$D$22 -> 17699.381 | I15: ='ايلان العوفي '!$D$23 -> 11231 | J15: =H15+I15 -> 28930.381
A16: 13 | B16: عبدالوهاب سليم | C16: 1 | D16: ='عبدالوهاب سليم'!$D$9 -> 27838.696 | E16: ='عبدالوهاب سليم'!$D$17 -> 2437.2216 | F16: ='عبدالوهاب سليم'!$D$20 -> 17781.032 | G16: ='عبدالوهاب سليم'!$D$21 -> 0 | H16: ='عبدالوهاب سليم'!$D$22 -> 17781.032 | I16: ='عبدالوهاب سليم'!$D$23 -> 0 | J16: =H16+I16 -> 17781.032
A17: 14 | B17: سلطان عواد الدبيسي | C17: 1 | D17: ='سلطان عواد الدبيسي'!$D$9 -> 21490 | E17: ='سلطان عواد الدبيسي'!$D$17 -> 1604.9 | F17: ='سلطان عواد الدبيسي'!$D$20 -> 13919.57 | G17: ='سلطان عواد الدبيسي'!$D$21 -> 0 | H17: ='سلطان عواد الدبيسي'!$D$22 -> 13919.57 | I17: ='سلطان عواد الدبيسي'!$D$23 -> 0 | J17: =H17+I17 -> 13919.57
A18: 15 | B18: لانا العوفي | C18: 1 | D18: ='لانا العوفي'!$D$9 -> 11030.922 | E18: ='لانا العوفي'!$D$17 -> 5541.506 | F18: ='لانا العوفي'!$D$20 -> 3842.591 | G18: ='لانا العوفي'!$D$21 -> 0 | H18: ='لانا العوفي'!$D$22 -> 3842.591 | I18: ='لانا العوفي'!$D$23 -> 5160 | J18: =H18+I18 -> 9002.591
A19: 16 | B19: مريم مسعد الصاعدي | C19: 4 | D19: =' مريم مسعد الصاعدي'!$X$9 -> 31029.565 | E19: =' مريم مسعد الصاعدي'!$X$17 -> 2547.9756 | F19: =' مريم مسعد الصاعدي'!$X$20 -> 19937.113 | G19: =' مريم مسعد الصاعدي'!$X$21 -> 0 | H19: =' مريم مسعد الصاعدي'!$X$22 -> 19937.113 | I19: =' مريم مسعد الصاعدي'!$X$23 -> 0 | J19: =H19+I19 -> 19937.113
A20: 17 | B20: فهد الغامدى | C20: 2 | D20: ='فهد الغامدي'!$N$9 -> 40786.226 | E20: ='فهد الغامدي'!$N$17 -> 4390.546 | F20: ='فهد الغامدي'!$N$20 -> 25476.976 | G20: ='فهد الغامدي'!$N$21 -> 0 | H20: ='فهد الغامدي'!$N$22 -> 25476.976 | I20: ='فهد الغامدي'!$N$23 -> 0 | J20: =H20+I20 -> 25476.976
A21: 18 | B21: عبيدالله مبارك العوفي | C21: 6 | D21: ='عبيدالله العوفى'!$AG$9 -> 133719.46 | E21: ='عبيدالله العوفى'!$AG$17 -> 16512.456 | F21: ='عبيدالله العوفى'!$AG$20 -> 82044.904 | G21: ='عبيدالله العوفى'!$AG$21 -> 25000 | H21: ='عبيدالله العوفى'!$AG$22 -> 57044.904 | I21: ='عبيدالله العوفى'!$AG$23 -> 0 | J21: =H21+I21 -> 57044.904
A22: 19 | B22: أم عبدالرحمن | C22: 1 | D22: ='ام عبدالرحمن'!$D$9 -> 16559.974 | E22: ='ام عبدالرحمن'!$D$17 -> 1641.6521 | F22: ='ام عبدالرحمن'!$D$20 -> 10442.825 | G22: ='ام عبدالرحمن'!$D$21 -> 0 | H22: ='ام عبدالرحمن'!$D$22 -> 10442.825 | I22: ='ام عبدالرحمن'!$D$23 -> 32480.546 | J22: =H22+I22 -> 42923.371
A23: 20 | B23: سامي عبيد الله العوفي | C23: 6 | D23: ='سامي عبيد الله العوفي'!$AG$9 -> 98568.53 | E23: ='سامي عبيد الله العوفي'!$AG$17 -> 12801.979 | F23: ='سامي عبيد الله العوفي'!$AG$20 -> 59497.213 | G23: ='سامي عبيد الله العوفي'!$AG$21 -> 0 | H23: ='سامي عبيد الله العوفي'!$AG$22 -> 59497.213 | I23: ='سامي عبيد الله العوفي'!$AG$23 -> 0 | J23: =H23+I23 -> 59497.213
A24: 21 | B24: نادر سليم الرشيدي | C24: 4 | D24: ='نادر سليم الرشيدي '!$X$9 -> 84998.122 | E24: ='نادر سليم الرشيدي '!$X$17 -> 17258.575 | F24: ='نادر سليم الرشيدي '!$X$20 -> 47417.683 | G24: ='نادر سليم الرشيدي '!$X$21 -> 0 | H24: ='نادر سليم الرشيدي '!$X$22 -> 47417.683 | I24: ='نادر سليم الرشيدي '!$X$23 -> 55148 | J24: =H24+I24 -> 102565.68
A25: 22 | B25: فهد منيف الحربي | C25: 3 | D25: =' فهد منيف الحربي'!$S$9 -> 78080.774 | E25: =' فهد منيف الحربي'!$S$17 -> 10719.968 | F25: =' فهد منيف الحربي'!$S$20 -> 47152.564 | G25: =' فهد منيف الحربي'!$S$21 -> 0 | H25: =' فهد منيف الحربي'!$S$22 -> 47152.564 | I25: =' فهد منيف الحربي'!$S$23 -> 46034 | J25: =H25+I25 -> 93186.564
A26: 23 | B26: بدور عبيدالله العوفى | C26: 1 | D26: =' بدور عبيد الله العوفي '!$D$9 -> 17975.652 | E26: =' بدور عبيد الله العوفي '!$D$17 -> 3530.1684 | F26: =' بدور عبيد الله العوفي '!$D$20 -> 10111.839 | G26: =' بدور عبيد الله العوفي '!$D$21 -> 0 | H26: =' بدور عبيد الله العوفي '!$D$22 -> 10111.839 | I26: =' بدور عبيد الله العوفي '!$D$23 -> 0 | J26: =H26+I26 -> 10111.839
A27: 24 | B27: عبدالرحمن محمد خضر الصاعدي | C27: 1 | D27: ='عبدالرحمن محمد خضر الصاعدي'!$D$9 -> 28027.687 | E27: ='عبدالرحمن محمد خضر الصاعدي'!$D$17 -> 3186.9141 | F27: ='عبدالرحمن محمد خضر الصاعدي'!$D$20 -> 17388.541 | G27: ='عبدالرحمن محمد خضر الصاعدي'!$D$21 -> 0 | H27: ='عبدالرحمن محمد خضر الصاعدي'!$D$22 -> 17388.541 | I27: ='عبدالرحمن محمد خضر الصاعدي'!$D$23 -> 0 | J27: =H27+I27 -> 17388.541
A28: 25 | B28: سعيد سلطان الشهراني | C28: 1 | D28: =' سعيد سلطان الشهراني'!$D$9 -> 28113.843 | E28: =' سعيد سلطان الشهراني'!$D$17 -> 2004.0695 | F28: =' سعيد سلطان الشهراني'!$D$20 -> 18276.842 | G28: =' سعيد سلطان الشهراني'!$D$21 -> 6000 | H28: =' سعيد سلطان الشهراني'!$D$22 -> 12276.842 | I28: =' سعيد سلطان الشهراني'!$D$23 -> 0 | J28: =H28+I28 -> 12276.842
A29: 26 | B29: غازى ناير الجهني | C29: 1 | D29: ='غازي ناير الجهني'!$D$9 -> 22717.391 | E29: ='غازي ناير الجهني'!$D$17 -> 1701.3832 | F29: ='غازي ناير الجهني'!$D$20 -> 14711.206 | G29: ='غازي ناير الجهني'!$D$21 -> 0 | H29: ='غازي ناير الجهني'!$D$22 -> 14711.206 | I29: ='غازي ناير الجهني'!$D$23 -> 11151 | J29: =H29+I29 -> 25862.206
A30: 27 | B30: غيث العوفى | C30: 2 | D30: ='غيث العوفي'!$N$9 -> 38554.243 | E30: ='غيث العوفي'!$N$17 -> 4541.0516 | F30: ='غيث العوفي'!$N$20 -> 23809.234 | G30: ='غيث العوفي'!$N$21 -> 0 | H30: ='غيث العوفي'!$N$22 -> 23809.234 | I30: ='غيث العوفي'!$N$23 -> 9969 | J30: =H30+I30 -> 33778.234
A31: 28 | B31: غلا العوفى | C31: 2 | D31: ='غلا العوفي'!$N$9 -> 27477.661 | E31: ='غلا العوفي'!$N$17 -> 3924.8481 | F31: ='غلا العوفي'!$N$20 -> 16486.969 | G31: ='غلا العوفي'!$N$21 -> 0 | H31: ='غلا العوفي'!$N$22 -> 16486.969 | I31: ='غلا العوفي'!$N$23 -> 9457 | J31: =H31+I31 -> 25943.969
A32: 29 | B32: حنان حمدان | C32: 1 | D32: ='حنان حمدان'!$D$9 -> 22259.565 | E32: ='حنان حمدان'!$D$17 -> 2092.7507 | F32: ='حنان حمدان'!$D$20 -> 14116.77 | G32: ='حنان حمدان'!$D$21 -> 0 | H32: ='حنان حمدان'!$D$22 -> 14116.77 | I32: ='حنان حمدان'!$D$23 -> 13693 | J32: =H32+I32 -> 27809.77
A33: 30 | B33: ابوغلا+ أبو لانا | C33: 2 | D33: ='ابو غلا + أبو لانا'!$N$9 -> 60116.443 | E33: ='ابو غلا + أبو لانا'!$N$17 -> 8063.212 | F33: ='ابو غلا + أبو لانا'!$N$20 -> 36437.262 | G33: ='ابو غلا + أبو لانا'!$N$21 -> 0 | H33: ='ابو غلا + أبو لانا'!$N$22 -> 36437.262 | I33: ='ابو غلا + أبو لانا'!$N$23 -> 75019 | J33: =H33+I33 -> 111456.26
A34: 31 | B34: احمد عبيد الله العوفى | C34: 2 | D34: ='احمد عبيدالله'!$N$9 -> 50685.402 | E34: ='احمد عبيدالله'!$N$17 -> 9895.0715 | F34: ='احمد عبيدالله'!$N$20 -> 28553.231 | G34: ='احمد عبيدالله'!$N$21 -> 0 | H34: ='احمد عبيدالله'!$N$22 -> 28553.231 | I34: ='احمد عبيدالله'!$N$23 -> 0 | J34: =H34+I34 -> 28553.231
A35: 32 | B35: احمد الشاماني | C35: 1 | D35: ='احمد الشاماني'!$D$9 -> 19061.043 | E35: ='احمد الشاماني'!$D$17 -> 3087.3072 | F35: ='احمد الشاماني'!$D$20 -> 11181.615 | G35: ='احمد الشاماني'!$D$21 -> 0 | H35: ='احمد الشاماني'!$D$22 -> 11181.615 | I35: ='احمد الشاماني'!$D$23 -> 0 | J35: =H35+I35 -> 11181.615
A36: 33 | B36: عبدالرحمن حمدان العوفى | C36: 1 | D36: ='عبدالرحمن حمدان العوفي'!$D$9 -> 47750.435 | E36: ='عبدالرحمن حمدان العوفي'!$D$17 -> 6897.4701 | F36: ='عبدالرحمن حمدان العوفي'!$D$20 -> 28597.075 | G36: ='عبدالرحمن حمدان العوفي'!$D$21 -> 0 | H36: ='عبدالرحمن حمدان العوفي'!$D$22 -> 28597.075 | I36: ='عبدالرحمن حمدان العوفي'!$D$23 -> -3146.829 | J36: =H36+I36 -> 25450.246
A37: 34 | B37: رايد حمدان العلوني الجهني | C37: 1 | D37: ='رايد حمدان العلوني الجهني'!$D$9 -> 18060.435 | E37: ='رايد حمدان العلوني الجهني'!$D$17 -> 1725.8431 | F37: ='رايد حمدان العلوني الجهني'!$D$20 -> 11434.214 | G37: ='رايد حمدان العلوني الجهني'!$D$21 -> 0 | H37: ='رايد حمدان العلوني الجهني'!$D$22 -> 11434.214 | I37: ='رايد حمدان العلوني الجهني'!$D$23 -> 0 | J37: =H37+I37 -> 11434.214
A38: 35 | B38: ماطر ناير راشد العلوني الجهني | C38: 1 | D38: ='ماطر ناير راشد العلواني الجهني'!$D$9 -> 17792.165 | E38: ='ماطر ناير راشد العلواني الجهني'!$D$17 -> 1926.6568 | F38: ='ماطر ناير راشد العلواني الجهني'!$D$20 -> 11105.856 | G38: ='ماطر ناير راشد العلواني الجهني'!$D$21 -> 0 | H38: ='ماطر ناير راشد العلواني الجهني'!$D$22 -> 11105.856 | I38: ='ماطر ناير راشد العلواني الجهني'!$D$23 -> 0 | J38: =H38+I38 -> 11105.856
A39: 36 | B39: ملك عبدالرحمن العوفي | C39: 2 | D39: ='ملك عبدالرحمن العوفى'!$N$9 -> 31119.774 | E39: ='ملك عبدالرحمن العوفى'!$N$17 -> 2735.066 | F39: ='ملك عبدالرحمن العوفى'!$N$20 -> 19869.296 | G39: ='ملك عبدالرحمن العوفى'!$N$21 -> 0 | H39: ='ملك عبدالرحمن العوفى'!$N$22 -> 19869.296 | I39: ='ملك عبدالرحمن العوفى'!$N$23 -> 0 | J39: =H39+I39 -> 19869.296
A40: 37 | J40: =H40+I40 -> 0
A41: 38 | J41: =H41+I41 -> 0
...

Sheet عبيدالله العوفى
A1: تقرير المستثمر : عبيدالله مبارك العوفي ( 31-12-2024 ) | F1: تقرير المستثمر : عبيدالله مبارك العوفي ( 31-12-2024 ) | K1: تقرير المستثمر : عبيدالله مبارك العوفي ( 31-12-2024 ) | P1: تقرير المستثمر : عبيدالله مبارك العوفي ( 31-12-2024 ) | T1: تقرير المستثمر : عبيدالله مبارك العوفي ( 31-12-2024 ) | Y1: تقرير المستثمر : عبيدالله مبارك العوفي ( 31-12-2024 ) | AD1: تقرير المستثمر : عبيدالله مبارك العوفي ( 31-12-2024 )
A2: نوع السيارة | C2: اتراج2022 | F2: نوع السيارة | H2: اتراج2022 | K2: نوع السيارة | M2: اتراج2022 | P2: نوع السيارة | R2: بيجاس2023 | T2: نوع السيارة | V2: يارس فضي 2021 | Y2: نوع السيارة | AA2: يارس فضي 2021 | AD2: نوع السيارة | AF2: =AA3&"- "&V3&"- "&R3&"- "&M3&"- "&H3&"- "&C3 -> 2074 DHU- 2072 DHU- ر ر س 5431- ر ا ل 7855- ر ا ل 7856- ر ا ل 7857
A3: رقم اللوحة | C3: ر ا ل 7857 | F3: رقم اللوحة | H3: ر ا ل 7856 | K3: رقم اللوحة | M3: ر ا ل 7855 | P3: رقم اللوحة | R3: ر ر س 5431 | T3: رقم اللوحة | V3: 2072 DHU | Y3: رقم اللوحة | AA3: 2074 DHU | AD3: رقم اللوحة
A5: الحساب | D5: المبلغ | F5: الحساب | I5: المبلغ | K5: الحساب | N5: المبلغ | P5: الحساب | S5: المبلغ | T5: الحساب | W5: المبلغ | Y5: الحساب | AB5: المبلغ | AD5: الحساب | AG5: المبلغ
A6: ايراد تشغيل والإصلاحات | D6: 24876.575 | F6: ايراد تشغيل والإصلاحات | I6: 17474.8 | K6: ايراد تشغيل والإصلاحات | N6: 23335.913 | P6: ايراد تشغيل والإصلاحات | S6: 28173.043 | T6: ايراد تشغيل والإصلاحات | W6: 19578.261 | Y6: ايراد تشغيل والإصلاحات | AB6: 18780.87 | AD6: ايراد تشغيل والإصلاحات | AG6: =AB6+W6+S6+N6+I6+D6 -> 132219.46
A7: تعويض شركات التأمين | D7: 0 | F7: تعويض شركات التأمين | I7: 0 | K7: تعويض شركات التأمين | N7: 0 | P7: تعويض شركات التأمين | S7: 0 | T7: تعويض شركات التأمين | W7: 0 | Y7: تعويض شركات التأمين | AB7: 0 | AD7: تعويض شركات التأمين | AG7: =AB7+W7+S7+N7+I7+D7 -> 0
A8: إيرادات مديونيات أعوام سابقة | D8: 0 | F8: إيرادات مديونيات أعوام سابقة | I8: 0 | K8: إيرادات مديونيات أعوام سابقة | N8: 1500 | P8: إيرادات مديونيات أعوام سابقة | S8: 0 | T8: إيرادات مديونيات أعوام سابقة | W8: 0 | Y8: إيرادات مديونيات أعوام سابقة | AB8: 0 | AD8: إيرادات مديونيات أعوام سابقة | AG8: =AB8+W8+S8+N8+I8+D8 -> 1500
A9: اجمالي ايراد السيارة | D9: =SUM(D6:D8) -> 24876.575 | F9: اجمالي ايراد السيارة | I9: =SUM(I6:I8) -> 17474.8 | K9: اجمالي ايراد السيارة | N9: =SUM(N6:N8) -> 24835.913 | P9: اجمالي ايراد السيارة | S9: =SUM(S6:S8) -> 28173.043 | T9: اجمالي ايراد السيارة | W9: =SUM(W6:W8) -> 19578.261 | Y9: اجمالي ايراد السيارة | AB9: =SUM(AB6:AB8) -> 18780.87 | AD9: اجمالي ايراد السيارة | AG9: =AB9+W9+S9+N9+I9+D9 -> 133719.46
A10: مصاريف نقل +اشتراكات أجهزة التتبع+بنزين +غسيل | D10: 204.01 | F10: مصاريف نقل +اشتراكات أجهزة التتبع+بنزين +غسيل | I10: 214 | K10: مصاريف نقل +اشتراكات أجهزة التتبع+بنزين +غسيل | N10: 392.7001 | P10: مصاريف نقل +اشتراكات أجهزة التتبع+بنزين +غسيل | S10: 184 | T10: مصاريف نقل +اشتراكات أجهزة التتبع+بنزين +غسيل | W10: 197.04 | Y10: مصاريف نقل +اشتراكات أجهزة التتبع+بنزين +غسيل | AB10: 284 | AD10: مصاريف نقل +اشتراكات أجهزة التتبع+بنزين +غسيل | AG10: =AB10+W10+S10+N10+I10+D10 -> 1475.7501
A11: مصروف فحص دوري وكرت تشغيل | D11: 0 | F11: مصروف فحص دوري وكرت تشغيل | I11: 0 | K11: مصروف فحص دوري وكرت تشغيل | N11: 0 | P11: مصروف فحص دوري وكرت تشغيل | S11: 0 | T11: مصروف فحص دوري وكرت تشغيل | W11: 133 | Y11: مصروف فحص دوري وكرت تشغيل | AB11: 100 | AD11: مصروف فحص دوري وكرت تشغيل | AG11: =AB11+W11+S11+N11+I11+D11 -> 233
A12: 2102 عمولات بنكية على المشتريات | D12: 94.394391 | F12: 2102 عمولات بنكية على المشتريات | I12: 63.562202 | K12: 2102 عمولات بنكية على المشتريات | N12: 184.96599 | P12: 2102 عمولات بنكية على المشتريات | S12: 151.39928 | T12: 2102 عمولات بنكية على المشتريات | W12: 3.8199959 | Y12: 2102 عمولات بنكية على المشتريات | AB12: 52.219607 | AD12: 2102 عمولات بنكية على المشتريات | AG12: =AB12+W12+S12+N12+I12+D12 -> 550.36147
A13: صيانة السيارات واصلاحات من حوادث | D13: =290+652.67 -> 942.67 | F13: صيانة السيارات واصلاحات من حوادث | I13: 1544.04 | K13: صيانة السيارات واصلاحات من حوادث | N13: 1092.89 | P13: صيانة السيارات واصلاحات من حوادث | S13: 1291.87 | T13: صيانة السيارات واصلاحات من حوادث | W13: 715.23 | Y13: صيانة السيارات واصلاحات من حوادث | AB13: 610.87 | AD13: صيانة السيارات واصلاحات من حوادث | AG13: =AB13+W13+S13+N13+I13+D13 -> 6197.57
A14: مصاريف تأمينات السيارات | D14: 0 | F14: مصاريف تأمينات السيارات | I14: 0 | K14: مصاريف تأمينات السيارات | N14: 0 | P14: مصاريف تأمينات السيارات | S14: 875.914 | T14: مصاريف تأمينات السيارات | W14: 875.91 | Y14: مصاريف تأمينات السيارات | AB14: 875.91 | AD14: مصاريف تأمينات السيارات | AG14: =AB14+W14+S14+N14+I14+D14 -> 2627.734
A15: مصاريف غيار زيت | D15: 393.27 | F15: مصاريف غيار زيت | I15: 671.09 | K15: مصاريف غيار زيت | N15: 791.08 | P15: مصاريف غيار زيت | S15: 654.12 | T15: مصاريف غيار زيت | W15: 950.21 | Y15: مصاريف غيار زيت | AB15: 393.27 | AD15: مصاريف غيار زيت | AG15: =AB15+W15+S15+N15+I15+D15 -> 3853.04
A16: مصروفات حكومية | D16: 300 | F16: مصروفات حكومية | I16: 375 | K16: مصروفات حكومية | N16: 300 | P16: مصروفات حكومية | T16: مصروفات حكومية | W16: 300 | Y16: مصروفات حكومية | AB16: 300 | AD16: مصروفات حكومية | AG16: =AB16+W16+S16+N16+I16+D16 -> 1575
A17: اجمـالى مصروفات التشغيل | D17: =SUM(D10:D16) -> 1934.3444 | F17: اجمـالى مصروفات التشغيل | I17: =SUM(I10:I16) -> 2867.6922 | K17: اجمـالى مصروفات التشغيل | N17: =SUM(N10:N16) -> 2761.6361 | P17: اجمـالى مصروفات التشغيل | S17: =SUM(S10:S16) -> 3157.3033 | T17: اجمـالى مصروفات التشغيل | W17: =SUM(W10:W16) -> 3175.21 | Y17: اجمـالى مصروفات التشغيل | AB17: =SUM(AB10:AB16) -> 2616.2696 | AD17: اجمـالى مصروفات التشغيل | AG17: =AB17+W17+S17+N17+I17+D17 -> 16512.456
A18: صافي الربح/الخسارة | D18: =D9-D17 -> 22942.23 | F18: صافي الربح/الخسارة | I18: =I9-I17 -> 14607.108 | K18: صافي الربح/الخسارة | N18: =N9-N17 -> 22074.277 | P18: صافي الربح/الخسارة | S18: =S9-S17 -> 25015.74 | T18: صافي الربح/الخسارة | W18: =W9-W17 -> 16403.051 | Y18: صافي الربح/الخسارة | AB18: =AB9-AB17 -> 16164.6 | AD18: صافي الربح/الخسارة | AG18: =AB18+W18+S18+N18+I18+D18 -> 117207.01
A19: نسبة التشغيل من الإيرادات (30%) | D19: =D18*0.3 -> 6882.6691 | F19: نسبة التشغيل من الإيرادات (30%) | I19: =I18*0.3 -> 4382.1323 | K19: نسبة التشغيل من الإيرادات (30%) | N19: =N18*0.3 -> 6622.2831 | P19: نسبة التشغيل من الإيرادات (30%) | S19: =S18*0.3 -> 7504.7221 | T19: نسبة التشغيل من الإيرادات (30%) | W19: =W18*0.3 -> 4920.9153 | Y19: نسبة التشغيل من الإيرادات (30%) | AB19: =AB18*0.3 -> 4849.38 | AD19: نسبة التشغيل من الإيرادات (30%) | AG19: =AB19+W19+S19+N19+I19+D19 -> 35162.102
A20: نسبة الربح من الإيرادات (70%) | D20: =D18-D19 -> 16059.561 | F20: نسبة الربح من الإيرادات (70%) | I20: =I18-I19 -> 10224.975 | K20: نسبة الربح من الإيرادات (70%) | N20: =N18-N19 -> 15451.994 | P20: نسبة الربح من الإيرادات (70%) | S20: =S18-S19 -> 17511.018 | T20: نسبة الربح من الإيرادات (70%) | W20: =W18-W19 -> 11482.136 | Y20: نسبة الربح من الإيرادات (70%) | AB20: =AB18-AB19 -> 11315.22 | AD20: نسبة الربح من الإيرادات (70%) | AG20: =AB20+W20+S20+N20+I20+D20 -> 82044.904
A21: ما تم سحبه من قبل المستمر | D21: 5000 | F21: ما تم سحبه من قبل المستمر | I21: 5000 | K21: ما تم سحبه من قبل المستمر | N21: 5000 | P21: ما تم سحبه من قبل المستمر | S21: 5000 | T21: ما تم سحبه من قبل المستمر | W21: 5000 | Y21: ما تم سحبه من قبل المستمر | AD21: ما تم سحبه من قبل المستمر | AG21: =AB21+W21+S21+N21+I21+D21 -> 25000
A22: المتبقي | D22: =D20-D21 -> 11059.561 | F22: المتبقي | I22: =I20-I21 -> 5224.9755 | K22: المتبقي | N22: =N20-N21 -> 10451.994 | P22: المتبقي | S22: =S20-S21 -> 12511.018 | T22: المتبقي | W22: =W20-W21 -> 6482.1356 | Y22: المتبقي | AB22: =AB20-AB21 -> 11315.22 | AD22: المتبقي | AG22: =AB22+W22+S22+N22+I22+D22 -> 57044.904
A23: رصيد سنوات سابقة | B23: رصيد سنوات سابقة | D23: 0 | F23: رصيد سنوات سابقة | G23: رصيد سنوات سابقة | I23: 0 | K23: رصيد سنوات سابقة | L23: رصيد سنوات سابقة | N23: 0 | P23: رصيد سنوات سابقة | Q23: رصيد سنوات سابقة | S23: 0 | T23: رصيد سنوات سابقة | U23: رصيد سنوات سابقة | W23: 0 | Y23: رصيد سنوات سابقة | Z23: رصيد سنوات سابقة | AB23: 0 | AD23: رصيد سنوات سابقة | AE23: رصيد سنوات سابقة | AG23: =AB23+W23+S23+N23+I23+D23 -> 0
A24: اجمالى الرصيد | B24: اجمالى الرصيد | D24: =D22+D23 -> 11059.561 | F24: اجمالى الرصيد | G24: اجمالى الرصيد | I24: =I22+I23 -> 5224.9755 | K24: اجمالى الرصيد | L24: اجمالى الرصيد | N24: =N22+N23 -> 10451.994 | P24: اجمالى الرصيد | Q24: اجمالى الرصيد | S24: =S22+S23 -> 12511.018 | T24: اجمالى الرصيد | U24: اجمالى الرصيد | W24: =W22+W23 -> 6482.1356 | Y24: اجمالى الرصيد | Z24: اجمالى الرصيد | AB24: =AB22+AB23 -> 11315.22 | AD24: اجمالى الرصيد | AE24: اجمالى الرصيد | AG24: =AB24+W24+S24+N24+I24+D24 -> 57044.904
F25: مديونية السيارة | K25: مديونية السيارة | Y25: مديونية السيارة
F26: الاسم | G26: تاريخ المطالبه | H26: رقم المطالبة | I26: مبلغ المديونية | K26: الاسم | L26: تاريخ المطالبة | M26: رقم المطالبه | N26: المبلغ | Y26: الاسم | Z26: تاريخ المطالبة | AA26: رقم المطالبه | AB26: المبلغ
F27: محمد احمد عبدالله المصباحي | G27: 2024 | H27: المتابعه مع الشئون القانونية | I27: 174.99 | K27: صالح زينهم عبدالعزيز حسن | L27: 2023 | M27: 401014001154405 | N27: 10074 | Y27: حنان دسوقي توفيق عبدالمنعم | Z27: 45199 | AA27: 401014501649117 | AB27: 2826.32 | AI27: المسحوبات
AH28: 10000 | AI28: 45389
AH29: 15000 | AI29: 45631

Sheet سامي عبيد الله العوفي
A1: تقرير المستثمر : سامي عبيد الله العوفي ( 31-12-2024 ) | F1: تقرير المستثمر : سامي عبيد الله العوفي ( 31-12-2024 ) | K1: تقرير المستثمر : سامي عبيد الله العوفي ( 31-12-2024 ) | P1: تقرير المستثمر : سامي عبيد الله العوفي ( 31-12-2024 ) | U1: تقرير المستثمر : سامي عبيد الله العوفي ( 31-12-2024 ) | Y1: تقرير المستثمر : سامي عبيد الله العوفي ( 31-12-2024 ) | AD1: تقرير المستثمر : سامي عبيد الله العوفي ( 31-12-2024 )
A2: نوع السيارة | C2: اتراج2022 | F2: نوع السيارة | H2: بيجاس2023 | K2: نوع السيارة | M2: هوينداي I10-2024 | P2: نوع السيارة | R2: هوينداي I10-2024 | U2: نوع السيارة | W2: هوينداي I10-2024 | Y2: نوع السيارة | AA2: يارس فضي 2021 | AD2: نوع السيارة | AF2: أتراج 2022-بيجاس 2023-يارس 2021 -هوينداي I10-2024
A3: رقم اللوحة | C3: ر ا ل 7847 | F3: رقم اللوحة | H3: ر ر س 5432 | K3: رقم اللوحة | M3: ر ك س 3590 | P3: رقم اللوحة | R3: ر ك س 3497 | U3: رقم اللوحة | W3: ر ك س 3498 | Y3: رقم اللوحة | AA3: 2066 د ه و | AD3: رقم اللوحة | AF3: =C3&"-"&H3&" - "&M3&" - "&R3&" - "&W3&" - "&AA3 -> ر ا ل 7847-ر ر س 5432 - ر ك س 3590 - ر ك س 3497 - ر ك س 3498 - 2066 د ه و
M4: تاريخ الإضافة 21-4-2024 | R4: تاريخ الإضافة 21-4-2024 | W4: تاريخ الإضافة 21-4-2024
A5: الحساب | D5: المبلغ | F5: الحساب | I5: المبلغ | K5: الحساب | N5: المبلغ | P5: الحساب | S5: المبلغ | U5: الحساب | X5: المبلغ | Y5: الحساب | AB5: المبلغ | AD5: الحساب | AG5: المبلغ
A6: ايراد تشغيل والإصلاحات | D6: 20752.174 | F6: ايراد تشغيل والإصلاحات | I6: 21065.217 | K6: ايراد تشغيل والإصلاحات | N6: 14111.296 | P6: ايراد تشغيل والإصلاحات | S6: 10360.87 | U6: ايراد تشغيل والإصلاحات | X6: 16278.974 | Y6: ايراد تشغيل والإصلاحات | AB6: 0 | AD6: ايراد تشغيل والإصلاحات | AG6: =D6+I6+N6+S6+X6+AB6 -> 82568.53
A7: تعويض شركات التأمين | D7: 0 | F7: تعويض شركات التأمين | I7: 16000 | K7: تعويض شركات التأمين | N7: 0 | P7: تعويض شركات التأمين | S7: 0 | U7: تعويض شركات التأمين | X7: 0 | Y7: تعويض شركات التأمين | AB7: 0 | AD7: تعويض شركات التأمين | AG7: =D7+I7+N7+S7+X7+AB7 -> 16000
A8: إيرادات مديونيات أعوام سابقة | D8: 0 | F8: إيرادات مديونيات أعوام سابقة | I8: 0 | K8: إيرادات مديونيات أعوام سابقة | N8: 0 | P8: إيرادات مديونيات أعوام سابقة | U8: إيرادات مديونيات أعوام سابقة | Y8: إيرادات مديونيات أعوام سابقة | AB8: 0 | AD8: إيرادات مديونيات أعوام سابقة | AG8: =D8+I8+N8+S8+X8+AB8 -> 0
A9: اجمالي ايراد السيارة | D9: =SUM(D6:D8) -> 20752.174 | F9: اجمالي ايراد السيارة | I9: =SUM(I6:I8) -> 37065.217 | K9: اجمالي ايراد السيارة | N9: =SUM(N6:N8) -> 14111.296 | P9: اجمالي ايراد السيارة | S9: =SUM(S6:S8) -> 10360.87 | U9: اجمالي ايراد السيارة | X9: =SUM(X6:X8) -> 16278.974 | Y9: اجمالي ايراد السيارة | AB9: =SUM(AB6:AB8) -> 0 | AD9: اجمالي ايراد السيارة | AG9: =D9+I9+N9+S9+X9+AB9 -> 98568.53
A10: مصاريف نقل +اشتراكات أجهزة التتبع+بنزين +غسيل | D10: 384.0001 | F10: مصاريف نقل +اشتراكات أجهزة التتبع+بنزين +غسيل | I10: 184 | K10: مصاريف نقل +اشتراكات أجهزة التتبع+بنزين +غسيل | N10: 63.39 | P10: مصاريف نقل +اشتراكات أجهزة التتبع+بنزين +غسيل | S10: 66 | U10: مصاريف نقل +اشتراكات أجهزة التتبع+بنزين +غسيل | X10: 46 | Y10: مصاريف نقل +اشتراكات أجهزة التتبع+بنزين +غسيل | AB10: 184 | AD10: مصاريف نقل +اشتراكات أجهزة التتبع+بنزين +غسيل | AG10: =D10+I10+N10+S10+X10+AB10 -> 927.3901
A11: مصروف فحص دوري وكرت تشغيل | D11: 0 | F11: مصروف فحص دوري وكرت تشغيل | I11: 0 | K11: مصروف فحص دوري وكرت تشغيل | N11: 0 | P11: مصروف فحص دوري وكرت تشغيل | S11: 0 | U11: مصروف فحص دوري وكرت تشغيل | X11: 0 | Y11: مصروف فحص دوري وكرت تشغيل | AB11: 133 | AD11: مصروف فحص دوري وكرت تشغيل | AG11: =D11+I11+N11+S11+X11+AB11 -> 133
A12: 2102 عمولات بنكية على المشتريات | D12: 97.740005 | F12: 2102 عمولات بنكية على المشتريات | I12: 159.85495 | K12: 2102 عمولات بنكية على المشتريات | N12: 81.55001 | P12: 2102 عمولات بنكية على المشتريات | S12: 7.41 | U12: 2102 عمولات بنكية على المشتريات | X12: 124.14 | Y12: 2102 عمولات بنكية على المشتريات | AD12: 2102 عمولات بنكية على المشتريات | AG12: =D12+I12+N12+S12+X12+AB12 -> 470.69497
A13: صيانة السيارات واصلاحات من حوادث | D13: 215.5 | F13: صيانة السيارات واصلاحات من حوادث | I13: 3420.3 | K13: صيانة السيارات واصلاحات من حوادث | N13: 0 | P13: صيانة السيارات واصلاحات من حوادث | S13: 0 | U13: صيانة السيارات واصلاحات من حوادث | X13: 0 | Y13: صيانة السيارات واصلاحات من حوادث | AB13: 80 | AD13: صيانة السيارات واصلاحات من حوادث | AG13: =D13+I13+N13+S13+X13+AB13 -> 3715.8
A14: مصاريف تأمينات السيارات | D14: 0 | F14: مصاريف تأمينات السيارات | I14: 875.914 | K14: مصاريف تأمينات السيارات | N14: 875.91 | P14: مصاريف تأمينات السيارات | S14: 875.91 | U14: مصاريف تأمينات السيارات | X14: 875.91 | Y14: مصاريف تأمينات السيارات | AB14: 875.91 | AD14: مصاريف تأمينات السيارات | AG14: =D14+I14+N14+S14+X14+AB14 -> 4379.554
A15: مصاريف غيار زيت | D15: 405 | F15: مصاريف غيار زيت | I15: 283.04 | K15: مصاريف غيار زيت | N15: 240 | P15: مصاريف غيار زيت | S15: 375 | U15: مصاريف غيار زيت | X15: 240 | Y15: مصاريف غيار زيت | AD15: مصاريف غيار زيت | AG15: =D15+I15+N15+S15+X15+AB15 -> 1543.04
A16: مصروفات حكومية | D16: 1050 | F16: مصروفات حكومية | I16: 57.5 | K16: مصروفات حكومية | N16: 0 | P16: مصروفات حكومية | U16: مصروفات حكومية | X16: 0 | Y16: مصروفات حكومية | AB16: 525 | AD16: مصروفات حكومية | AG16: =D16+I16+N16+S16+X16+AB16 -> 1632.5
A17: اجمـالى مصروفات التشغيل | D17: =SUM(D10:D16) -> 2152.2401 | F17: اجمـالى مصروفات التشغيل | I17: =SUM(I10:I16) -> 4980.609 | K17: اجمـالى مصروفات التشغيل | N17: =SUM(N10:N16) -> 1260.85 | P17: اجمـالى مصروفات التشغيل | S17: =SUM(S10:S16) -> 1324.32 | U17: اجمـالى مصروفات التشغيل | X17: =SUM(X10:X16) -> 1286.05 | Y17: اجمـالى مصروفات التشغيل | AB17: =SUM(AB10:AB16) -> 1797.91 | AD17: اجمـالى مصروفات التشغيل | AG17: =D17+I17+N17+S17+X17+AB17 -> 12801.979
A18: صافي الربح/الخسارة | D18: =D9-D17 -> 18599.934 | F18: صافي الربح/الخسارة | I18: =I9-I17 -> 32084.608 | K18: صافي الربح/الخسارة | N18: =N9-N17 -> 12850.446 | P18: صافي الربح/الخسارة | S18: =S9-S17 -> 9036.5496 | U18: صافي الربح/الخسارة | X18: =X9-X17 -> 14992.924 | Y18: صافي الربح/الخسارة | AB18: =AB9-AB17 -> -1797.91 | AD18: صافي الربح/الخسارة | AG18: =D18+I18+N18+S18+X18+AB18 -> 85766.551
A19: نسبة التشغيل من الإيرادات (30%) | D19: =D18*0.3 -> 5579.9801 | F19: نسبة التشغيل من الإيرادات (30%) | I19: =I18*0.3 -> 9625.3825 | K19: نسبة التشغيل من الإيرادات (30%) | N19: =N18*0.3 -> 3855.1337 | P19: نسبة التشغيل من الإيرادات (30%) | S19: =S18*0.3 -> 2710.9649 | U19: نسبة التشغيل من الإيرادات (30%) | X19: =X18*0.3 -> 4497.8772 | Y19: نسبة التشغيل من الإيرادات (30%) | AB19: 0 | AD19: نسبة التشغيل من الإيرادات (30%) | AG19: =D19+I19+N19+S19+X19+AB19 -> 26269.338
A20: نسبة الربح من الإيرادات (70%) | D20: =D18-D19 -> 13019.954 | F20: نسبة الربح من الإيرادات (70%) | I20: =I18-I19 -> 22459.226 | K20: نسبة الربح من الإيرادات (70%) | N20: =N18-N19 -> 8995.3119 | P20: نسبة الربح من الإيرادات (70%) | S20: =S18-S19 -> 6325.5847 | U20: نسبة الربح من الإيرادات (70%) | X20: =X18-X19 -> 10495.047 | Y20: نسبة الربح من الإيرادات (70%) | AB20: =AB18-AB19 -> -1797.91 | AD20: نسبة الربح من الإيرادات (70%) | AG20: =D20+I20+N20+S20+X20+AB20 -> 59497.213
A21: ما تم سحبه من قبل المستمر | F21: ما تم سحبه من قبل المستمر | K21: ما تم سحبه من قبل المستمر | P21: ما تم سحبه من قبل المستمر | U21: ما تم سحبه من قبل المستمر | Y21: ما تم سحبه من قبل المستمر | AB21: 0 | AD21: ما تم سحبه من قبل المستمر | AG21: =D21+I21+N21+S21+X21+AB21 -> 0
A22: المتبقي | D22: =D20-D21 -> 13019.954 | F22: المتبقي | I22: =I20-I21 -> 22459.226 | K22: المتبقي | N22: =N20-N21 -> 8995.3119 | P22: المتبقي | S22: =S20-S21 -> 6325.5847 | U22: المتبقي | X22: =X20-X21 -> 10495.047 | Y22: المتبقي | AB22: =AB20-AB21 -> -1797.91 | AD22: المتبقي | AG22: =D22+I22+N22+S22+X22+AB22 -> 59497.213
A23: رصيد سنوات سابقة | B23: رصيد سنوات سابقة | F23: رصيد سنوات سابقة | G23: رصيد سنوات سابقة | K23: رصيد سنوات سابقة | L23: رصيد سنوات سابقة | P23: رصيد سنوات سابقة | Q23: رصيد سنوات سابقة | U23: رصيد سنوات سابقة | V23: رصيد سنوات سابقة | Y23: رصيد سنوات سابقة | Z23: رصيد سنوات سابقة | AB23: 0 | AD23: رصيد سنوات سابقة | AE23: رصيد سنوات سابقة | AG23: =D23+I23+N23+S23+X23+AB23 -> 0
A24: اجمالى الرصيد | B24: اجمالى الرصيد | D24: =D22+D23 -> 13019.954 | F24: اجمالى الرصيد | G24: اجمالى الرصيد | I24: =I22+I23 -> 22459.226 | K24: اجمالى الرصيد | L24: اجمالى الرصيد | N24: =N22+N23 -> 8995.3119 | P24: اجمالى الرصيد | Q24: اجمالى الرصيد | S24: =S22+S23 -> 6325.5847 | U24: اجمالى الرصيد | V24: اجمالى الرصيد | X24: =X22+X23 -> 10495.047 | Y24: اجمالى الرصيد | Z24: اجمالى الرصيد | AB24: =AB22+AB23 -> -1797.91 | AD24: اجمالى الرصيد | AE24: اجمالى الرصيد | AG24: =D24+I24+N24+S24+X24+AB24 -> 59497.213
L25: قيمة السيارة | N25: 50571 | Q25: قيمة السيارة | S25: 50571 | V25: قيمة السيارة | X25: 50571 | Y25: مديونية السيارة | AD25: المدفوع من سامي ( حولات بنكية ) | AG25: 128000
Y26: الاسم | Z26: تاريخ المطالبة | AA26: رقم المطالبه | AB26: المبلغ | AD26: اجمالى قيمة السيارات حسب عرض السعر المرسل | AG26: =50571*3 -> 151713
Y27: محمود عبدالحليم محمود محمد | Z27: 45220 | AA27: 401014501694085 | AB27: 15279.12 | AD27: المتبقى عليه من قيمة السيارات بعد خصم الأرباح والمبلغ المدفوع من قبله | AG27: =AG24+AG25-AG26 -> 35784.213

Sheet احمد عبيدالله
A1: تقرير المستثمر : احمد عبيدالله مبارك العوفي ( 31-12-2024 ) | F1: تقرير المستثمر : احمد عبيدالله مبارك العوفي ( 31-12-2024 ) | K1: تقرير المستثمر : احمد عبيدالله مبارك العوفي ( 31-12-2024 )
A2: نوع السيارة | C2: يارس أبيض 2021 | F2: نوع السيارة | H2: يارس فضي 2021 | K2: نوع السيارة | M2: =H2&" - "&C2 -> يارس فضي 2021 - يارس أبيض 2021
A3: رقم اللوحة | C3: 2075 DHU | F3: رقم اللوحة | H3: 2064 د ه و | K3: رقم اللوحة | M3: =C3&"-"&H3 -> 2075 DHU-2064 د ه و
A5: الحساب | D5: المبلغ | F5: الحساب | I5: المبلغ | K5: الحساب | N5: المبلغ
A6: ايراد تشغيل والإصلاحات | D6: 26802.609 | F6: ايراد تشغيل والإصلاحات | I6: 21913.043 | K6: ايراد تشغيل والإصلاحات | N6: =D6+I6 -> 48715.652
A7: تعويض شركات التأمين | D7: 0 | F7: تعويض شركات التأمين | I7: 1969.75 | K7: تعويض شركات التأمين | N7: =D7+I7 -> 1969.75
A8: إيرادات مديونيات أعوام سابقة | D8: 0 | F8: إيرادات مديونيات أعوام سابقة | I8: 0 | K8: إيرادات مديونيات أعوام سابقة | N8: =D8+I8 -> 0
A9: اجمالي ايراد السيارة | D9: =SUM(D6:D8) -> 26802.609 | F9: اجمالي ايراد السيارة | I9: =SUM(I6:I8) -> 23882.793 | K9: اجمالي ايراد السيارة | N9: =D9+I9 -> 50685.402
A10: مصاريف نقل +اشتراكات أجهزة التتبع+بنزين +غسيل | D10: 814.7201 | F10: مصاريف نقل +اشتراكات أجهزة التتبع+بنزين +غسيل | I10: 204 | K10: مصاريف نقل +اشتراكات أجهزة التتبع+بنزين +غسيل | N10: =D10+I10 -> 1018.7201
A11: مصروف فحص دوري وكرت تشغيل | D11: 100 | F11: مصروف فحص دوري وكرت تشغيل | I11: 100 | K11: مصروف فحص دوري وكرت تشغيل | N11: =D11+I11 -> 200
A12: 2102 عمولات بنكية على المشتريات | D12: 108.3604 | F12: 2102 عمولات بنكية على المشتريات | I12: 1.9 | K12: 2102 عمولات بنكية على المشتريات | N12: =D12+I12 -> 110.2604
A13: صيانة السيارات واصلاحات من حوادث | D13: 3252.781 | F13: صيانة السيارات واصلاحات من حوادث | I13: 1654.33 | K13: صيانة السيارات واصلاحات من حوادث | N13: =D13+I13 -> 4907.111
A14: مصاريف تأمينات السيارات | D14: 875.91 | F14: مصاريف تأمينات السيارات | I14: 875.91 | K14: مصاريف تأمينات السيارات | N14: =D14+I14 -> 1751.82
A15: مصاريف غيار زيت | D15: 924.12 | F15: مصاريف غيار زيت | I15: 133.04 | K15: مصاريف غيار زيت | N15: =D15+I15 -> 1057.16
A16: مصروفات حكومية | D16: 300 | F16: مصروفات حكومية | I16: 550 | K16: مصروفات حكومية | N16: =D16+I16 -> 850
A17: اجمـالى مصروفات التشغيل | D17: =SUM(D10:D16) -> 6375.8915 | F17: اجمـالى مصروفات التشغيل | I17: =SUM(I10:I16) -> 3519.18 | K17: اجمـالى مصروفات التشغيل | N17: =D17+I17 -> 9895.0715
A18: صافي الربح/الخسارة | D18: =D9-D17 -> 20426.717 | F18: صافي الربح/الخسارة | I18: =I9-I17 -> 20363.613 | K18: صافي الربح/الخسارة | N18: =D18+I18 -> 40790.331
A19: نسبة التشغيل من الإيرادات (30%) | D19: =D18*0.3 -> 6128.0152 | F19: نسبة التشغيل من الإيرادات (30%) | I19: =I18*0.3 -> 6109.084 | K19: نسبة التشغيل من الإيرادات (30%) | N19: =D19+I19 -> 12237.099
A20: نسبة الربح من الإيرادات (70%) | D20: =D18-D19 -> 14298.702 | F20: نسبة الربح من الإيرادات (70%) | I20: =I18-I19 -> 14254.529 | K20: نسبة الربح من الإيرادات (70%) | N20: =D20+I20 -> 28553.231
A21: ما تم سحبه من قبل المستمر | F21: ما تم سحبه من قبل المستمر | K21: ما تم سحبه من قبل المستمر | N21: =D21+I21 -> 0
A22: المتبقي | D22: =D20-D21 -> 14298.702 | F22: المتبقي | I22: =I20-I21 -> 14254.529 | K22: المتبقي | N22: =D22+I22 -> 28553.231
A23: رصيد سنوات سابقة | B23: رصيد سنوات سابقة | D23: 0 | F23: رصيد سنوات سابقة | G23: رصيد سنوات سابقة | I23: 0 | K23: رصيد سنوات سابقة | L23: رصيد سنوات سابقة | N23: =D23+I23 -> 0
A24: اجمالى الرصيد | B24: اجمالى الرصيد | D24: =D22+D23 -> 14298.702 | F24: اجمالى الرصيد | G24: اجمالى الرصيد | I24: =I22+I23 -> 14254.529 | K24: اجمالى الرصيد | L24: اجمالى الرصيد | N24: =D24+I24 -> 28553.231

Sheet مقبل ناجي عوض العلوني
A1: تقرير المستثمر : مقبل ناجي عوض العلوني ( 31-12-2024 ) | F1: تقرير المستثمر : مقبل ناجي عوض العلوني ( 31-12-2024 ) | K1: تقرير المستثمر : مقبل ناجي عوض العلوني ( 31-12-2024 ) | P1: تقرير المستثمر : مقبل ناجي عوض العلوني ( 31-12-2024 ) | U1: تقرير المستثمر : مقبل ناجي عوض العلوني ( 31-12-2024 ) | Z1: تقرير المستثمر : مقبل ناجي عوض العلوني ( 31-12-2024 ) | AE1: تقرير المستثمر : مقبل ناجي عوض العلوني ( 31-12-2024 ) - اجمالى السيارات
A2: نوع السيارة | C2: بيجاس2022 | F2: نوع السيارة | H2: اكسنت2020 | K2: نوع السيارة | M2: اتراج2022 | P2: نوع السيارة | R2: يارس 2023 | U2: نوع السيارة | W2: يارس فضي 2021 | Z2: نوع السيارة | AB2: يارس أبيض 2021 | AE2: العدد | AG2: 6
A3: رقم اللوحة | C3: د ي ر 9714 | F3: رقم اللوحة | H3: د م ا 9368 | K3: رقم اللوحة | M3: د ل ص 4738 | P3: رقم اللوحة | R3: 1232 ر د ب | U3: رقم اللوحة | W3: 2067 د ه و | Z3: رقم اللوحة | AB3: 2068 د ه و | AE3: =C3&"- "&H3&" - "&M3&" - "&R3&" - "&W3&" - "&AB3 -> د ي ر 9714- د م ا 9368 - د ل ص 4738 - 1232 ر د ب - 2067 د ه و - 2068 د ه و
A5: الحساب | D5: المبلغ | F5: الحساب | I5: المبلغ | K5: الحساب | N5: المبلغ | P5: الحساب | S5: المبلغ | U5: الحساب | X5: المبلغ | Z5: الحساب | AC5: المبلغ | AE5: الحساب | AH5: المبلغ
A6: ايراد تشغيل والإصلاحات | D6: 23150.443 | F6: ايراد تشغيل والإصلاحات | I6: 26421.652 | K6: ايراد تشغيل والإصلاحات | N6: 18217.391 | P6: ايراد تشغيل والإصلاحات | S6: =29299.3565217391-300 -> 28999.357 | U6: ايراد تشغيل والإصلاحات | X6: 18440.435 | Z6: ايراد تشغيل | AC6: 7129.5652 | AE6: ايراد تشغيل | AH6: =D6+I6+N6+S6+X6+AC6 -> 122358.84
A7: تعويض شركات التأمين | D7: 0 | F7: تعويض شركات التأمين | I7: 0 | K7: تعويض شركات التأمين | N7: 0 | P7: تعويض شركات التأمين | S7: 0 | U7: تعويض شركات التأمين | X7: 0 | Z7: تعويض شركات التأمين | AC7: 13340 | AE7: تعويض شركات التأمين | AH7: =D7+I7+N7+S7+X7+AC7 -> 13340
A8: إيرادات مديونيات أعوام سابقة | D8: 0 | F8: إيرادات مديونيات أعوام سابقة | I8: 0 | K8: إيرادات مديونيات أعوام سابقة | P8: إيرادات مديونيات أعوام سابقة | S8: 300 | U8: إيرادات مديونيات أعوام سابقة | X8: 0 | Z8: إيرادات مديونيات أعوام سابقة | AC8: 0 | AE8: إيرادات مديونيات أعوام سابقة | AH8: =D8+I8+N8+S8+X8+AC8 -> 300
A9: اجمالي ايراد السيارة | D9: =SUM(D6:D8) -> 23150.443 | F9: اجمالي ايراد السيارة | I9: =SUM(I6:I8) -> 26421.652 | K9: اجمالي ايراد السيارة | N9: =SUM(N6:N8) -> 18217.391 | P9: اجمالي ايراد السيارة | S9: =SUM(S6:S8) -> 29299.357 | U9: اجمالي ايراد السيارة | X9: =SUM(X6:X8) -> 18440.435 | Z9: اجمالي ايراد السيارة | AC9: =SUM(AC6:AC8) -> 20469.565 | AE9: اجمالي ايراد السيارة | AH9: =D9+I9+N9+S9+X9+AC9 -> 135998.84
A10: مصاريف نقل +اشتراكات أجهزة التتبع+بنزين +غسيل | D10: 184 | F10: مصاريف نقل +اشتراكات أجهزة التتبع+بنزين +غسيل | I10: 184 | K10: مصاريف نقل +اشتراكات أجهزة التتبع+بنزين +غسيل | N10: 184 | P10: مصاريف نقل +اشتراكات أجهزة التتبع+بنزين +غسيل | S10: 201.39 | U10: مصاريف نقل +اشتراكات أجهزة التتبع+بنزين +غسيل | X10: 325.96 | Z10: مصاريف نقل +اشتراكات أجهزة التتبع+بنزين +غسيل | AC10: =234+400 -> 634 | AE10: مصاريف نقل +اشتراكات أجهزة التتبع+بنزين +غسيل | AH10: =D10+I10+N10+S10+X10+AC10 -> 1713.35
A11: مصروف فحص دوري وكرت تشغيل | D11: 0 | F11: مصروف فحص دوري وكرت تشغيل | I11: 0 | K11: مصروف فحص دوري وكرت تشغيل | N11: 0 | P11: مصروف فحص دوري وكرت تشغيل | S11: 0 | U11: مصروف فحص دوري وكرت تشغيل | X11: 100 | Z11: مصروف فحص دوري وكرت تشغيل | AC11: 100 | AE11: مصروف فحص دوري وكرت تشغيل | AH11: =D11+I11+N11+S11+X11+AC11 -> 200
A12: 2102 عمولات بنكية على المشتريات | D12: 173.99275 | F12: 2102 عمولات بنكية على المشتريات | I12: 0 | K12: 2102 عمولات بنكية على المشتريات | N12: 1.84 | P12: 2102 عمولات بنكية على المشتريات | S12: 135.61003 | U12: 2102 عمولات بنكية على المشتريات | X12: 100.33384 | Z12: 2102 عمولات بنكية على المشتريات | AC12: 0 | AE12: 2102 عمولات بنكية على المشتريات | AH12: =D12+I12+N12+S12+X12+AC12 -> 411.77662
A13: صيانة السيارات واصلاحات من حوادث | D13: 78.48 | F13: صيانة السيارات واصلاحات من حوادث | I13: 574.36 | K13: صيانة السيارات واصلاحات من حوادث | N13: 798.11 | P13: صيانة السيارات واصلاحات من حوادث | S13: 1253.69 | U13: صيانة السيارات واصلاحات من حوادث | X13: 2330.4325 | Z13: صيانة السيارات واصلاحات من حوادث | AC13: 13087.67 | AE13: صيانة السيارات واصلاحات من حوادث | AH13: =D13+I13+N13+S13+X13+AC13 -> 18122.743
A14: مصاريف تأمينات السيارات | D14: 875.91 | F14: مصاريف تأمينات السيارات | I14: 875.91 | K14: مصاريف تأمينات السيارات | N14: 0 | P14: مصاريف تأمينات السيارات | S14: 875.91 | U14: مصاريف تأمينات السيارات | X14: 875.91 | Z14: مصاريف تأمينات السيارات | AC14: 875.91 | AE14: مصاريف تأمينات السيارات | AH14: =D14+I14+N14+S14+X14+AC14 -> 4379.55
A15: مصاريف غيار زيت | D15: 506.97 | F15: مصاريف غيار زيت | I15: =227.4+34.78 -> 262.18 | K15: مصاريف غيار زيت | N15: 444.56 | P15: مصاريف غيار زيت | S15: 401.09 | U15: مصاريف غيار زيت | X15: 133.04 | Z15: مصاريف غيار زيت | AC15: 135 | AE15: مصاريف غيار زيت | AH15: =D15+I15+N15+S15+X15+AC15 -> 1882.84
A16: مصروفات حكومية | D16: 0 | F16: مصروفات حكومية | I16: 300 | K16: مصروفات حكومية | N16: 300 | P16: مصروفات حكومية | S16: 613 | U16: مصروفات حكومية | X16: 300 | Z16: مصروفات حكومية | AC16: 500 | AE16: مصروفات حكومية | AH16: =D16+I16+N16+S16+X16+AC16 -> 2013
A17: اجمـالى مصروفات التشغيل | D17: =SUM(D10:D16) -> 1819.3528 | F17: اجمـالى مصروفات التشغيل | I17: =SUM(I10:I16) -> 2196.45 | K17: اجمـالى مصروفات التشغيل | N17: =SUM(N10:N16) -> 1728.51 | P17: اجمـالى مصروفات التشغيل | S17: =SUM(S10:S16) -> 3480.69 | U17: اجمـالى مصروفات التشغيل | X17: =SUM(X10:X16) -> 4165.6763 | Z17: اجمـالى مصروفات التشغيل | AC17: =SUM(AC10:AC16) -> 15332.58 | AE17: اجمـالى مصروفات التشغيل | AH17: =D17+I17+N17+S17+X17+AC17 -> 28723.259
A18: صافي الربح/الخسارة | D18: =D9-D17 -> 21331.091 | F18: صافي الربح/الخسارة | I18: =I9-I17 -> 24225.202 | K18: صافي الربح/الخسارة | N18: =N9-N17 -> 16488.881 | P18: صافي الربح/الخسارة | S18: =S9-S17 -> 25818.666 | U18: صافي الربح/الخسارة | X18: =X9-X17 -> 14274.758 | Z18: صافي الربح/الخسارة | AC18: =AC9-AC17 -> 5136.9852 | AE18: صافي الربح/الخسارة | AH18: =D18+I18+N18+S18+X18+AC18 -> 107275.58
A19: نسبة التشغيل من الإيرادات (30%) | D19: =D18*0.3 -> 6399.3272 | F19: نسبة التشغيل من الإيرادات (30%) | I19: =I18*0.3 -> 7267.5607 | K19: نسبة التشغيل من الإيرادات (30%) | N19: =N18*0.3 -> 4946.6644 | P19: نسبة التشغيل من الإيرادات (30%) | S19: =S18*0.3 -> 7745.5999 | U19: نسبة التشغيل من الإيرادات (30%) | X19: =X18*0.3 -> 4282.4275 | Z19: نسبة التشغيل من الإيرادات (30%) | AC19: =AC18*0.3 -> 1541.0956 | AE19: نسبة التشغيل من الإيرادات (30%) | AH19: =D19+I19+N19+S19+X19+AC19 -> 32182.675
A20: نسبة الربح من الإيرادات (70%) | D20: =D18-D19 -> 14931.764 | F20: نسبة الربح من الإيرادات (70%) | I20: =I18-I19 -> 16957.642 | K20: نسبة الربح من الإيرادات (70%) | N20: =N18-N19 -> 11542.217 | P20: نسبة الربح من الإيرادات (70%) | S20: =S18-S19 -> 18073.067 | U20: نسبة الربح من الإيرادات (70%) | X20: =X18-X19 -> 9992.3309 | Z20: نسبة الربح من الإيرادات (70%) | AC20: =AC18-AC19 -> 3595.8897 | AE20: نسبة الربح من الإيرادات (70%) | AH20: =D20+I20+N20+S20+X20+AC20 -> 75092.909
A21: ما تم سحبه من قبل المستمر | F21: ما تم سحبه من قبل المستمر | K21: ما تم سحبه من قبل المستمر | N21: 0 | P21: ما تم سحبه من قبل المستمر | S21: 0 | U21: ما تم سحبه من قبل المستمر | X21: 0 | Z21: ما تم سحبه من قبل المستمر | AC21: 0 | AE21: ما تم سحبه من قبل المستمر | AH21: =D21+I21+N21+S21+X21+AC21 -> 0
A22: المتبقي | D22: =D20-D21 -> 14931.764 | F22: المتبقي | I22: =I20-I21 -> 16957.642 | K22: المتبقي | N22: =N20-N21 -> 11542.217 | P22: المتبقي | S22: =S20-S21 -> 18073.067 | U22: المتبقي | X22: =X20-X21 -> 9992.3309 | Z22: المتبقي | AC22: =AC20-AC21 -> 3595.8897 | AE22: المتبقي | AH22: =D22+I22+N22+S22+X22+AC22 -> 75092.909
A23: رصيد سنوات سابقة | B23: رصيد سنوات سابقة | D23: 12791 | F23: رصيد سنوات سابقة | G23: رصيد سنوات سابقة | I23: 0 | K23: رصيد سنوات سابقة | L23: رصيد سنوات سابقة | N23: 0 | P23: رصيد سنوات سابقة | Q23: رصيد سنوات سابقة | S23: 0 | U23: رصيد سنوات سابقة | V23: رصيد سنوات سابقة | X23: 0 | Z23: رصيد سنوات سابقة | AA23: رصيد سنوات سابقة | AC23: 0 | AE23: رصيد سنوات سابقة | AF23: رصيد سنوات سابقة | AH23: =D23+I23+N23+S23+X23+AC23 -> 12791
A24: اجمالى الرصيد | B24: اجمالى الرصيد | D24: =D22+D23 -> 27722.764 | F24: اجمالى الرصيد | G24: اجمالى الرصيد | I24: =I22+I23 -> 16957.642 | K24: اجمالى الرصيد | L24: اجمالى الرصيد | N24: =N22+N23 -> 11542.217 | P24: اجمالى الرصيد | Q24: اجمالى الرصيد | S24: =S22+S23 -> 18073.067 | U24: اجمالى الرصيد | V24: اجمالى الرصيد | X24: =X22+X23 -> 9992.3309 | Z24: اجمالى الرصيد | AA24: اجمالى الرصيد | AC24: =AC22+AC23 -> 3595.8897 | AE24: اجمالى الرصيد | AF24: اجمالى الرصيد | AH24: =D24+I24+N24+S24+X24+AC24 -> 87883.909
A25: مديونية السيارة | F25: مديونية السيارة | K25: مديونية السيارة | P25: مديونية السيارة | U25: مديونية السيارة
A26: الاسم | B26: تاريخ المطالبه | C26: رقم المطالبة | D26: مبلغ المديونية | F26: الاسم | G26: تاريخ المطالبه | H26: رقم المطالبه | I26: المبلغ | K26: الاسم | L26: تاريخ المطالبة | M26: رقم المطالبة | N26: المبلغ | P26: الاسم | Q26: تاريخ المطالبه | R26: رقم المطالبه | S26: المبلغ | U26: الاسم | V26: تاريخ المطالبه | W26: رقم المطالبه | X26: المبلغ
A27: فواز بن سلمان بن سمران المحياوي | B27: 44916 | C27: 401014401133659 | D27: 11584 | F27: عبدالله وهيب محمد طباخ | G27: 44423 | H27: 401014401445227 | I27: 5143.55 | K27: جميل نور احمد امداد حسين منير الزمان | L27: 2023 | M27: 401014401007388 | N27: 18140 | P27: احمد رجاءالله الرفاعي | Q27: 2023 | R27: المتابعة مع الشئون القانونية | S27: 11900.4 | U27: فهد علي مصلح العوفي | V27: 45045 | W27: 401014401342814 | X27: 13591.82
K28: عبدالمجيد محسن | L28: 45557 | M28: تم الرفع وفق سند لأمر | N28: 2816.51
W37: =V37+V29 -> 0

Sheet فايز رابح الشاماني
A1: تقرير المستثمر : فايز رابح الشاماني ( 31-12-2024 ) | F1: تقرير المستثمر : فايز رابح الشاماني ( 31-12-2024 ) | K1: تقرير المستثمر : فايز رابح الشاماني ( 31-12-2024 ) | P1: تقرير المستثمر : فايز رابح الشاماني ( 31-12-2024 ) | U1: تقرير المستثمر : فايز رابح الشاماني ( 31-12-2024 )
A2: نوع السيارة | C2: يارس فضي 2021 | F2: نوع السيارة | H2: يارس أبيض 2021 | K2: نوع السيارة | M2: تويوتا يارس -2024 | P2: نوع السيارة | R2: سزوكي دزير -2024 | U2: نوع السيارة | W2: =R2&" - "&M2&" - "&H2&" - "&C2 -> سزوكي دزير -2024 - تويوتا يارس -2024 - يارس أبيض 2021 - يارس فضي 2021
A3: رقم اللوحة | C3: 2071 DHU | F3: رقم اللوحة | H3: 2073 DHU | K3: رقم اللوحة | M3: ر ق و3938 | P3: رقم اللوحة | R3: ر ق ه 6756 | U3: رقم اللوحة | W3: =H3&" - "& C3&" - "&M3&" - "&R3 -> 2073 DHU - 2071 DHU - ر ق و3938 - ر ق ه 6756
M4: تاريخ الإضافة 4-4-2024 | S4: تاريخ الاضافة 21-4-2024
A5: الحساب | D5: المبلغ | F5: الحساب | I5: المبلغ | K5: الحساب | N5: المبلغ | P5: الحساب | S5: المبلغ | U5: الحساب | X5: المبلغ
A6: ايراد تشغيل والإصلاحات | D6: 17884.626 | F6: ايراد تشغيل والإصلاحات | I6: 18981.896 | K6: ايراد تشغيل والإصلاحات | N6: 16481.574 | P6: ايراد تشغيل والإصلاحات | S6: 17033.035 | U6: ايراد تشغيل والإصلاحات | X6: =I6+D6+S6+N6 -> 70381.13
A7: تعويض شركات التأمين | D7: 0 | F7: تعويض شركات التأمين | I7: 0 | K7: تعويض شركات التأمين | N7: 0 | P7: تعويض شركات التأمين | S7: 0 | U7: تعويض شركات التأمين | X7: =I7+D7+S7+N7 -> 0
A8: إيرادات مديونيات أعوام سابقة | D8: 0 | F8: إيرادات مديونيات أعوام سابقة | I8: 0 | K8: إيرادات مديونيات أعوام سابقة | N8: 0 | P8: إيرادات مديونيات أعوام سابقة | S8: 0 | U8: إيرادات مديونيات أعوام سابقة | X8: =I8+D8+S8+N8 -> 0
A9: اجمالي ايراد السيارة | D9: =SUM(D6:D8) -> 17884.626 | F9: اجمالي ايراد السيارة | I9: =SUM(I6:I8) -> 18981.896 | K9: اجمالي ايراد السيارة | N9: =SUM(N6:N8) -> 16481.574 | P9: اجمالي ايراد السيارة | S9: =SUM(S6:S8) -> 17033.035 | U9: اجمالي ايراد السيارة | X9: =I9+D9+S9+N9 -> 70381.13
A10: مصاريف نقل +اشتراكات أجهزة التتبع+بنزين +غسيل | D10: 201.39 | F10: مصاريف نقل +اشتراكات أجهزة التتبع+بنزين +غسيل | I10: 856.83 | K10: مصاريف نقل +اشتراكات أجهزة التتبع+بنزين +غسيل | N10: 46 | P10: مصاريف نقل +اشتراكات أجهزة التتبع+بنزين +غسيل | S10: 46 | U10: مصاريف نقل +اشتراكات أجهزة التتبع+بنزين +غسيل | X10: =I10+D10+S10+N10 -> 1150.22
A11: مصروف فحص دوري وكرت تشغيل | D11: 133 | F11: مصروف فحص دوري وكرت تشغيل | I11: 100 | K11: مصروف فحص دوري وكرت تشغيل | N11: 0 | P11: مصروف فحص دوري وكرت تشغيل | S11: 0 | U11: مصروف فحص دوري وكرت تشغيل | X11: =I11+D11+S11+N11 -> 233
A12: 2102 عمولات بنكية على المشتريات | D12: 0 | F12: 2102 عمولات بنكية على المشتريات | I12: 47.210002 | K12: 2102 عمولات بنكية على المشتريات | N12: 119.57 | P12: 2102 عمولات بنكية على المشتريات | S12: 59.542 | U12: 2102 عمولات بنكية على المشتريات | X12: =I12+D12+S12+N12 -> 226.322
A13: صيانة السيارات واصلاحات من حوادث | D13: 874.13 | F13: صيانة السيارات واصلاحات من حوادث | I13: 2616.82 | K13: صيانة السيارات واصلاحات من حوادث | N13: 25 | P13: صيانة السيارات واصلاحات من حوادث | S13: 30 | U13: صيانة السيارات واصلاحات من حوادث | X13: =I13+D13+S13+N13 -> 3545.95
A14: مصاريف تأمينات السيارات | D14: 875.91 | F14: مصاريف تأمينات السيارات | I14: 875.91 | K14: مصاريف تأمينات السيارات | N14: 875.91 | P14: مصاريف تأمينات السيارات | S14: 875.91 | U14: مصاريف تأمينات السيارات | X14: =I14+D14+S14+N14 -> 3503.64
A15: مصاريف غيار زيت | D15: 791.08 | F15: مصاريف غيار زيت | I15: 830.01 | K15: مصاريف غيار زيت | N15: 375 | P15: مصاريف غيار زيت | S15: 750 | U15: مصاريف غيار زيت | X15: =I15+D15+S15+N15 -> 2746.09
A16: مصروفات حكومية | D16: 300 | F16: مصروفات حكومية | I16: 300 | K16: مصروفات حكومية | N16: 0 | P16: مصروفات حكومية | S16: 0 | U16: مصروفات حكومية | X16: =I16+D16+S16+N16 -> 600
A17: اجمـالى مصروفات التشغيل | D17: =SUM(D10:D16) -> 3175.51 | F17: اجمـالى مصروفات التشغيل | I17: =SUM(I10:I16) -> 5626.78 | K17: اجمـالى مصروفات التشغيل | N17: =SUM(N10:N16) -> 1441.48 | P17: اجمـالى مصروفات التشغيل | S17: =SUM(S10:S16) -> 1761.452 | U17: اجمـالى مصروفات التشغيل | X17: =I17+D17+S17+N17 -> 12005.222
A18: صافي الربح/الخسارة | D18: =D9-D17 -> 14709.116 | F18: صافي الربح/الخسارة | I18: =I9-I17 -> 13355.116 | K18: صافي الربح/الخسارة | N18: =N9-N17 -> 15040.094 | P18: صافي الربح/الخسارة | S18: =S9-S17 -> 15271.583 | U18: صافي الربح/الخسارة | X18: =I18+D18+S18+N18 -> 58375.908
A19: نسبة التشغيل من الإيرادات (30%) | D19: =D18*0.3 -> 4412.7348 | F19: نسبة التشغيل من الإيرادات (30%) | I19: =I18*0.3 -> 4006.5347 | K19: نسبة التشغيل من الإيرادات (30%) | N19: =N18*0.3 -> 4512.0282 | P19: نسبة التشغيل من الإيرادات (30%) | S19: =S18*0.3 -> 4581.4748 | U19: نسبة التشغيل من الإيرادات (30%) | X19: =I19+D19+S19+N19 -> 17512.773
A20: نسبة الربح من الإيرادات (70%) | D20: =D18-D19 -> 10296.381 | F20: نسبة الربح من الإيرادات (70%) | I20: =I18-I19 -> 9348.581 | K20: نسبة الربح من الإيرادات (70%) | N20: =N18-N19 -> 10528.066 | P20: نسبة الربح من الإيرادات (70%) | S20: =S18-S19 -> 10690.108 | U20: نسبة الربح من الإيرادات (70%) | X20: =I20+D20+S20+N20 -> 40863.136
A21: ما تم سحبه من قبل المستمر | D21: 0 | F21: ما تم سحبه من قبل المستمر | I21: 0 | K21: ما تم سحبه من قبل المستمر | N21: 0 | P21: ما تم سحبه من قبل المستمر | S21: 0 | U21: ما تم سحبه من قبل المستمر | X21: =I21+D21+S21+N21 -> 0
A22: المتبقي | D22: =D20-D21 -> 10296.381 | F22: المتبقي | I22: =I20-I21 -> 9348.581 | K22: المتبقي | N22: =N20-N21 -> 10528.066 | P22: المتبقي | S22: =S20-S21 -> 10690.108 | U22: المتبقي | X22: =I22+D22+S22+N22 -> 40863.136
A23: رصيد سنوات سابقة | B23: رصيد سنوات سابقة | D23: 0 | F23: رصيد سنوات سابقة | G23: رصيد سنوات سابقة | I23: 0 | K23: رصيد سنوات سابقة | L23: رصيد سنوات سابقة | N23: 0 | P23: رصيد سنوات سابقة | Q23: رصيد سنوات سابقة | S23: 0 | U23: رصيد سنوات سابقة | V23: رصيد سنوات سابقة | X23: =I23+D23+S23+N23 -> 0
A24: اجمالى الرصيد | B24: اجمالى الرصيد | D24: =D22+D23 -> 10296.381 | F24: اجمالى الرصيد | G24: اجمالى الرصيد | I24: =I22+I23 -> 9348.581 | K24: اجمالى الرصيد | L24: اجمالى الرصيد | N24: =N22+N23 -> 10528.066 | P24: اجمالى الرصيد | Q24: اجمالى الرصيد | S24: =S22+S23 -> 10690.108 | U24: اجمالى الرصيد | V24: اجمالى الرصيد | X24: =I24+D24+S24+N24 -> 40863.136
A25: مديونية السيارة | F25: مديونية السيارة
A26: الاسم | B26: تاريخ المطالبه | C26: رقم المطالبه | D26: المبلغ | F26: الاسم | G26: تاريخ المطالبة | H26: حالة المطالبة | I26: المبلغ
A27: احمد يوسف عمران القعيمري الرشيدي | B27: 2022 | C27: المتابعة مع الشئون القانونية | D27: 1200 | F27: محمد وليد احمد الزيني | G27: 2022 | H27: المتابعه مع الشئون القانونية | I27: 436.9
A28: محمد علي توفيق حجازي | B28: 45177 | C28: 401014501608164 | D28: 3022
A29: تركي فليح العنزي | B29: 45222 | C29: 401014501696737 | D29: 1415.36
A30: الإجمالي | D30: =D27+D28+D29 -> 5637.36
C33: =B33+B40 -> 0

Sheet احمد الشاماني
A1: تقرير المستثمر : احمد الشاماني ( 31-12-2024 )
A2: نوع السيارة | C2: بيجاس 2023
A3: رقم اللوحة | C3: ر د ن 1016
A5: الحساب | D5: المبلغ
A6: ايراد تشغيل والإصلاحات | D6: 19061.043
A7: تعويض شركات التأمين | D7: 0
A8: إيرادات مديونيات أعوام سابقة | D8: 0
A9: اجمالي ايراد السيارة | D9: =SUM(D6:D8) -> 19061.043
A10: مصاريف نقل +اشتراكات أجهزة التتبع+بنزين +غسيل | D10: 258.79
A11: مصروف فحص دوري وكرت تشغيل | D11: 0
A12: عمولات بنكية على المشتريات | D12: 96.085181
A13: صيانة السيارات واصلاحات من حوادث | D13: 1453.482
A14: مصاريف تأمينات السيارات | D14: 875.91
A15: مصاريف غيار زيت | D15: 403.04
A16: مصروفات حكومية | D16: 0
A17: اجمـالى مصروفات التشغيل | D17: =SUM(D10:D16) -> 3087.3072
A18: صافي الربح/الخسارة | D18: =D9-D17 -> 15973.736
A19: نسبة التشغيل من الإيرادات (30%) | D19: =D18*0.3 -> 4792.1209
A20: نسبة الربح من الإيرادات (70%) | D20: =D18-D19 -> 11181.615
A21: ما تم سحبه من قبل المستمر | D21: 0
A22: المتبقي | D22: =D20-D21 -> 11181.615
A23: رصيد سنوات سابقة | B23: رصيد سنوات سابقة | D23: 0
A24: اجمالى الرصيد | B24: اجمالى الرصيد | D24: =D22+D23 -> 11181.615
A25: مديونية السيارة
A26: الاسم | B26: تاريخ المطالبه | C26: رقم المطالبة | D26: مبلغ المديونية
A27: لينا عدنان يوسف ابوسلامه | B27: 45668 | C27: 401014602774421 | D27: 4976.66

Sheet غازي ناير الجهني
A1: تقرير المستثمر : غازي ناير الجهني ( 31-12-2024 )
A2: نوع السيارة | C2: بيجاس 2023
A3: رقم اللوحة | C3: ر ر س 6029
A5: الحساب | D5: المبلغ
A6: ايراد تشغيل والإصلاحات | D6: 22717.391
A7: تعويض شركات التأمين | D7: 0
A8: إيرادات مديونيات أعوام سابقة | D8: 0
A9: اجمالي ايراد السيارة | D9: =SUM(D6:D8) -> 22717.391
A10: مصاريف نقل +اشتراكات أجهزة التتبع+بنزين +غسيل | D10: 184
A11: مصروف فحص دوري وكرت تشغيل | D11: 0
A12: 2102 عمولات بنكية على المشتريات | D12: 115.14921
A13: صيانة السيارات واصلاحات من حوادث | D13: 0
A14: مصاريف تأمينات السيارات | D14: 875.914
A15: مصاريف غيار زيت | D15: 526.32
A16: مصروفات حكومية | D16: 0
A17: اجمـالى مصروفات التشغيل | D17: =SUM(D10:D16) -> 1701.3832
A18: صافي الربح/الخسارة | D18: =D9-D17 -> 21016.008
A19: نسبة التشغيل من الإيرادات (30%) | D19: =D18*0.3 -> 6304.8024
A20: نسبة الربح من الإيرادات (70%) | D20: =D18-D19 -> 14711.206
A21: ما تم سحبه من قبل المستمر | D21: 0
A22: المتبقي | D22: =D20-D21 -> 14711.206
A23: رصيد سنوات سابقة +فرق مبلغ شراء السيارة 1600 ريال | B23: رصيد سنوات سابقة | D23: =9551+1600 -> 11151
A24: اجمالى الرصيد | B24: اجمالى الرصيد | D24: =D22+D23 -> 25862.206

Sheet رائد الحسيني
A1: تقرير المستثمر : رائد الحسيني ( 31-12-2024 )
A2: نوع السيارة | C2: يارس أبيض 2021
A3: رقم اللوحة | C3: 2070 DHU
A5: الحساب | D5: المبلغ
A6: ايراد تشغيل والإصلاحات | D6: 0
A7: تعويض شركات التأمين | D7: 35343
A8: إيرادات مديونيات أعوام سابقة | D8: 0
A9: اجمالي ايراد السيارة | D9: =SUM(D6:D8) -> 35343
A10: مصاريف نقل +اشتراكات أجهزة التتبع+بنزين +غسيل
A11: مصروف فحص دوري وكرت تشغيل
A12: 2102 عمولات بنكية على المشتريات
A13: صيانة السيارات واصلاحات من حوادث
A14: مصاريف تأمينات السيارات
A15: مصاريف غيار زيت
A16: مصروفات حكومية
A17: اجمـالى مصروفات التشغيل | D17: =SUM(D10:D16) -> 0
A18: صافي الربح/الخسارة | D18: =D9-D17 -> 35343
A19: نسبة التشغيل من الإيرادات (30%) | D19: 0
A20: نسبة الربح من الإيرادات (70%) | D20: =D18-D19 -> 35343
A21: ما تم سحبه من قبل المستمر | D21: 35343
A22: المتبقي | D22: =D20-D21 -> 0
A23: رصيد سنوات سابقة | B23: رصيد سنوات سابقة | D23: 0
A24: اجمالى الرصيد | B24: اجمالى الرصيد | D24: =D22+D23 -> 0
A25: مديونية السيارة
A26: الاسم | B26: تاريخ المطالبة | C26: رقم المطالبه | D26: المبلغ
A27: محمد مشعل عويد المهلكي المطيري | B27: المتابعه مه الشئون القانونية | C27: 401014400876063 | D27: 1500
A28: هشام عبدالله احمد ابو حمود | B28: 44786 | C28: 401014400885417 | D28: 3071.5
A29: الإجمالي | D29: =SUM(D27:D28) -> 4571.5
A30: تاريخ الحادث يوم 2022/12/3
A31: تاريخ التالف 2023/1/9 تم وصول المبلغ من شركة التأمين
A32: مبلغ مطالبة شركة تامين الراجحي = 35344

Sheet مرام الصاعدي
A1: تقرير المستثمر : مرام الصاعدي ( 31-12-2024 )
A2: نوع السيارة | C2: بيجاس2022
A3: رقم اللوحة | C3: د ي ر 9713
A5: الحساب | D5: المبلغ
A6: ايراد تشغيل والإصلاحات | D6: 19305.757
A7: تعويض شركات التأمين | D7: 0
A8: إيرادات مديونيات أعوام سابقة | D8: 0
A9: اجمالي ايراد السيارة | D9: =SUM(D6:D8) -> 19305.757
A10: مصاريف نقل +اشتراكات أجهزة التتبع+بنزين +غسيل | D10: 184
A11: مصروف فحص دوري وكرت تشغيل | D11: 0
A12: 2102 عمولات بنكية على المشتريات | D12: 58.090151
A13: صيانة السيارات واصلاحات من حوادث | D13: 839.13
A14: مصاريف تأمينات السيارات | D14: 875.91
A15: مصاريف غيار زيت | D15: 476.95
A16: مصروفات حكومية | D16: 0
A17: اجمـالى مصروفات التشغيل | D17: =SUM(D10:D16) -> 2434.0802
A18: صافي الربح/الخسارة | D18: =D9-D17 -> 16871.676
A19: نسبة التشغيل من الإيرادات (30%) | D19: =D18*0.3 -> 5061.5029
A20: نسبة الربح من الإيرادات (70%) | D20: =D18-D19 -> 11810.173
A21: ما تم سحبه من قبل المستمر | D21: 0
A22: المتبقي | D22: =D20-D21 -> 11810.173
A23: رصيد سنوات سابقة | B23: رصيد سنوات سابقة | D23: 10590
A24: اجمالى الرصيد | B24: اجمالى الرصيد | D24: =D22+D23 -> 22400.173

Sheet بدرية الصاعدي
A1: تقرير المستثمر : بدرية الصاعدي ( 31-12-2024 )
A2: نوع السيارة | C2: بيجاس2022
A3: رقم اللوحة | C3: د ي ر 9712
A5: الحساب | D5: المبلغ
A6: ايراد تشغيل والإصلاحات | D6: 25326.522
A7: تعويض شركات التأمين | D7: 0
A8: إيرادات مديونيات أعوام سابقة | D8: 0
A9: اجمالي ايراد السيارة | D9: =SUM(D6:D8) -> 25326.522
A10: مصاريف نقل +اشتراكات أجهزة التتبع+بنزين +غسيل | D10: 279.65
A11: مصروف فحص دوري وكرت تشغيل | D11: 0
A12: 2102 عمولات بنكية على المشتريات | D12: 76.430001
A13: صيانة السيارات واصلاحات من حوادث | D13: 1442.11
A14: مصاريف تأمينات السيارات | D14: 875.91
A15: مصاريف غيار زيت | D15: 671.09
A16: مصروفات حكومية | D16: 225
A17: اجمـالى مصروفات التشغيل | D17: =SUM(D10:D16) -> 3570.19
A18: صافي الربح/الخسارة | D18: =D9-D17 -> 21756.332
A19: نسبة التشغيل من الإيرادات (30%) | D19: =D18*0.3 -> 6526.8995
A20: نسبة الربح من الإيرادات (70%) | D20: =D18-D19 -> 15229.432
A21: ما تم سحبه من قبل المستمر
A22: المتبقي | D22: =D20-D21 -> 15229.432
A23: رصيد سنوات سابقة | B23: رصيد سنوات سابقة | D23: 30811
A24: اجمالى الرصيد | B24: اجمالى الرصيد | D24: =D22+D23 -> 46040.432

Sheet روان مسعد
A1: تقرير المستثمر : روان مسعد ( 31-12-2024 )
A2: نوع السيارة | C2: بيجاس2022
A3: رقم اللوحة | C3: د ي ر 9711
A5: الحساب | D5: المبلغ
A6: ايراد تشغيل والإصلاحات | D6: 16670.235
A7: تعويض شركات التأمين | D7: 0
A8: إيرادات مديونيات أعوام سابقة | D8: 0
A9: اجمالي ايراد السيارة | D9: =SUM(D6:D8) -> 16670.235
A10: مصاريف نقل +اشتراكات أجهزة التتبع+بنزين +غسيل | D10: 184
A11: مصروف فحص دوري وكرت تشغيل | D11: 0
A12: 2102 عمولات بنكية على المشتريات | D12: 180.21998
A13: صيانة السيارات واصلاحات من حوادث | D13: 583.44
A14: مصاريف تأمينات السيارات | D14: 875.91
A15: مصاريف غيار زيت | D15: 386.08
A16: مصروفات حكومية | D16: 0
A17: اجمـالى مصروفات التشغيل | D17: =SUM(D10:D16) -> 2209.65
A18: صافي الربح/الخسارة | D18: =D9-D17 -> 14460.585
A19: نسبة التشغيل من الإيرادات (30%) | D19: =D18*0.3 -> 4338.1754
A20: نسبة الربح من الإيرادات (70%) | D20: =D18-D19 -> 10122.409
A21: ما تم سحبه من قبل المستمر
A22: المتبقي | D22: =D20-D21 -> 10122.409
A23: رصيد سنوات سابقة | B23: رصيد سنوات سابقة | D23: 24302.125
A24: اجمالى الرصيد | B24: اجمالى الرصيد | D24: =SUM(D22:D23) -> 34424.534
A25: مديونية السيارة
A26: الاسم | B26: تاريخ المطالبة | C26: رقم المطالبه | D26: المبلغ
A27: فيصل مرزوق منور الردادي | B27: 45221 | C27: 401014400996346 | D27: 13172.24

Sheet اميره +نسرين الصاعدي
A1: تقرير المستثمر : اميره +نسرين الصاعدي ( 31-12-2024 )
A2: نوع السيارة | C2: بيجاس2022
A3: رقم اللوحة | C3: د ي ر 9710
A5: الحساب | D5: المبلغ
A6: ايراد تشغيل والإصلاحات | D6: 28898.07
A7: تعويض شركات التأمين | D7: 0
A8: إيرادات مديونيات أعوام سابقة | D8: 0
A9: اجمالي ايراد السيارة | D9: =SUM(D6:D8) -> 28898.07
A10: مصاريف نقل +اشتراكات أجهزة التتبع+بنزين +غسيل | D10: 184
A11: مصروف فحص دوري وكرت تشغيل | D11: 0
A12: 2102 عمولات بنكية على المشتريات | D12: 151.59203
A13: صيانة السيارات واصلاحات من حوادث | D13: 1494.5
A14: مصاريف تأمينات السيارات | D14: 875.91
A15: مصاريف غيار زيت | D15: 526.32
A16: مصروفات حكومية | D16: 0
A17: اجمـالى مصروفات التشغيل | D17: =SUM(D10:D16) -> 3232.322
A18: صافي الربح/الخسارة | D18: =D9-D17 -> 25665.748
A19: نسبة التشغيل من الإيرادات (30%) | D19: =D18*0.3 -> 7699.7243
A20: نسبة الربح من الإيرادات (70%) | D20: =D18-D19 -> 17966.023
A21: ما تم سحبه من قبل المستمر | D21: 0
A22: المتبقي | D22: =D20-D21 -> 17966.023
A23: رصيد سنوات سابقة | B23: رصيد سنوات سابقة | D23: 27322.382
A24: اجمالى الرصيد | B24: اجمالى الرصيد | D24: =SUM(D22:D23) -> 45288.405

Sheet نوال حمدان
A1: تقرير المستثمر : نوال حمدان ( 31-12-2024 ) | F1: تقرير المستثمر : نوال حمدان ( 31-12-2024 ) | K1: تقرير المستثمر : نوال حمدان ( 31-12-2024 )
A2: نوع السيارة | C2: بيجاس2022 | F2: نوع السيارة | H2: بيجاس2023 | K2: نوع السيارة
A3: رقم اللوحة | C3: د ي ر9573 | F3: رقم اللوحة | H3: ر ر س 5466 | K3: رقم اللوحة | M3: =H3&"-"&C3 -> ر ر س 5466 -د ي ر9573
A5: الحساب | D5: المبلغ | F5: الحساب | I5: المبلغ | K5: الحساب | N5: المبلغ
A6: ايراد تشغيل والإصلاحات | D6: 19764.348 | F6: ايراد تشغيل والإصلاحات | I6: 19219.713 | K6: ايراد تشغيل | N6: =D6+I6 -> 38984.061
A7: تعويض شركات التأمين | D7: 0 | F7: تعويض شركات التأمين | I7: 0 | K7: تعويض شركات التأمين | N7: =D7+I7 -> 0
A8: إيرادات مديونيات أعوام سابقة | D8: 0 | F8: إيرادات مديونيات أعوام سابقة | I8: 0 | K8: إيرادات مديونيات أعوام سابقة | N8: =D8+I8 -> 0
A9: اجمالي ايراد السيارة | D9: =SUM(D6:D8) -> 19764.348 | F9: اجمالي ايراد السيارة | I9: =SUM(I6:I8) -> 19219.713 | K9: اجمالي ايراد السيارة | N9: =D9+I9 -> 38984.061
A10: مصاريف نقل +اشتراكات أجهزة التتبع+بنزين +غسيل | D10: 901.39 | F10: مصاريف نقل +اشتراكات أجهزة التتبع+بنزين +غسيل | I10: 204 | K10: مصاريف نقل +اشتراكات أجهزة التتبع+بنزين +غسيل | N10: =D10+I10 -> 1105.39
A11: مصروف فحص دوري وكرت تشغيل | D11: 0 | F11: مصروف فحص دوري وكرت تشغيل | I11: 0 | K11: مصروف فحص دوري وكرت تشغيل | N11: =D11+I11 -> 0
